Workbook

Sheet P3
A1: PID | B1: Last | C1: First | D1: Data model (30) | E1: REST API (30) | F1: Tests (20) | G1: Code quality (15) | H1: README (5) | I1: Late days | J1: Total | K1: Comment
A2: aalvar73 | B2: Alvarez | C2: Anika | D2: 30 | E2: 30 | F2: 20 | G2: 15 | H2: 3 | I2: 0 | J2: =SUM(D2:H2)-IF(I2>1,5*(I2-1),0) | K2: hard-coded API key in config, -2
A3: halvar44 | B3: Alvarez | C3: Hana | D3: 29 | E3: 30 | F3: 20 | G3: 13 | H3: 5 | I3: 0 | J3: =SUM(D3:H3)-IF(I3>1,5*(I3-1),0) | K3: README missing run instructions
A4: ebarne26 | B4: Barnes | C4: Ellie | D4: 30 | E4: 27 | F4: 14 | G4: 15 | H4: 4 | I4: 0 | J4: =SUM(D4:H4)-IF(I4>1,5*(I4-1),0)
A5: lbarne46 | B5: Barnes | C5: Lucas | D5: 29 | E5: 20 | F5: 20 | G5: 14 | H5: 5 | I5: 0 | J5: =SUM(D5:H5)-IF(I5>1,5*(I5-1),0)
A6: vbarne79 | B6: Barnes | C6: Victor | D6: 27 | E6: 30 | F6: 19 | G6: 14 | H6: 5 | I6: 2 | J6: =SUM(D6:H6)-IF(I6>1,5*(I6-1),0)
A7: jbenne73 | B7: Bennett | C7: Jacob | D7: 30 | E7: 28 | F7: 20 | G7: 14 | H7: 5 | I7: 0 | J7: =SUM(D7:H7)-IF(I7>1,5*(I7-1),0)
A8: ecasti77 | B8: Castillo | C8: Ethan | D8: 30 | E8: 29 | F8: 14 | G8: 14 | H8: 3 | I8: 0 | J8: =SUM(D8:H8)-IF(I8>1,5*(I8-1),0)
A9: gcasti55 | B9: Castillo | C9: Grace | D9: 30 | E9: 30 | F9: 19 | G9: 15 | H9: 5 | I9: 0 | J9: =SUM(D9:H9)-IF(I9>1,5*(I9-1),0)
A10: lcasti27 | B10: Castillo | C10: Leah | D10: 29 | E10: 27 | F10: 19 | G10: 13 | H10: 5 | I10: 0 | J10: =SUM(D10:H10)-IF(I10>1,5*(I10-1),0)
A11: rchowd60 | B11: Chowdhury | C11: Rosa | D11: 29 | E11: 29 | F11: 20 | G11: 15 | H11: 5 | I11: 0 | J11: =SUM(D11:H11)-IF(I11>1,5*(I11-1),0)
A12: cdawso9 | B12: Dawson | C12: Chloe | D12: 28 | E12: 29 | F12: 20 | G12: 15 | H12: 4 | I12: 0 | J12: =SUM(D12:H12)-IF(I12>1,5*(I12-1),0)
A13: gdawso56 | B13: Dawson | C13: Grace | D13: 29 | E13: 20 | F13: 20 | G13: 15 | H13: 4 | I13: 2 | J13: =SUM(D13:H13)-IF(I13>1,5*(I13-1),0) | K13: no error handling on fetch
A14: ldawso94 | B14: Dawson | C14: Logan | D14: 30 | E14: 30 | F14: 20 | G14: 13 | H14: 4 | I14: 0 | J14: =SUM(D14:H14)-IF(I14>1,5*(I14-1),0)
A15: rdawso79 | B15: Dawson | C15: Ryan | D15: 30 | E15: 29 | F15: 20 | G15: 15 | H15: 5 | I15: 0 | J15: =SUM(D15:H15)-IF(I15>1,5*(I15-1),0)
A16: mdelga29 | B16: Delgado | C16: Maya | D16: 28 | E16: 30 | F16: 14 | G16: 10 | H16: 4 | I16: 0 | J16: =SUM(D16:H16)-IF(I16>1,5*(I16-1),0)
A17: dellis12 | B17: Ellis | C17: Daniel | D17: 20 | E17: 30 | F17: 19 | G17: 10 | H17: 5 | I17: 0 | J17: =SUM(D17:H17)-IF(I17>1,5*(I17-1),0) | K17: great UI polish
A18: cfitzg19 | B18: Fitzgerald | C18: Caleb | D18: 30 | E18: 30 | F18: 20 | G18: 15 | H18: 5 | I18: 0 | J18: =SUM(D18:H18)-IF(I18>1,5*(I18-1),0) | K18: nice test coverage
A19: efitzg9 | B19: Fitzgerald | C19: Ethan | D19: 30 | E19: 28 | F19: 20 | G19: 15 | H19: 3 | I19: 0 | J19: =SUM(D19:H19)-IF(I19>1,5*(I19-1),0)
A20: vfitzg44 | B20: Fitzgerald | C20: Victor | D20: 29 | E20: 30 | F20: 18 | G20: 15 | H20: 5 | I20: 0 | J20: =SUM(D20:H20)-IF(I20>1,5*(I20-1),0)
A21: nfoste50 | B21: Foster | C21: Noah | D21: 28 | E21: 29 | F21: 14 | G21: 14 | H21: 5 | I21: 0 | J21: =SUM(D21:H21)-IF(I21>1,5*(I21-1),0) | K21: no error handling on fetch
A22: agreen67 | B22: Greene | C22: Arjun | D22: 30 | E22: 20 | F22: 18 | G22: 13 | H22: 5 | I22: 0 | J22: =SUM(D22:H22)-IF(I22>1,5*(I22-1),0) | K22: no error handling on fetch
A23: igreen46 | B23: Greene | C23: Isabel | D23: 27 | E23: 20 | F23: 19 | G23: 15 | H23: 4 | I23: 1 | J23: =SUM(D23:H23)-IF(I23>1,5*(I23-1),0) | K23: hard-coded API key in config, -2
A24: mgreen47 | B24: Greene | C24: Marco | D24: 30 | E24: 20 | F24: 20 | G24: 15 | H24: 3 | I24: 0 | J24: =SUM(D24:H24)-IF(I24>1,5*(I24-1),0)
A25: agupta99 | B25: Gupta | C25: Anika | D25: 28 | E25: 20 | F25: 19 | G25: 10 | H25: 4 | I25: 0 | J25: =SUM(D25:H25)-IF(I25>1,5*(I25-1),0)
A26: khale16 | B26: Hale | C26: Kyle | D26: 28 | E26: 30 | F26: 17 | G26: 12 | H26: 4 | I26: 0 | J26: =SUM(D26:H26)-IF(I26>1,5*(I26-1),0) | K26: routes not RESTful
A27: shale29 | B27: Hale | C27: Sofia | D27: 30 | E27: 30 | F27: 20 | G27: 15 | H27: 5 | I27: 2 | J27: =SUM(D27:H27)-IF(I27>1,5*(I27-1),0)
A28: nholt27 | B28: Holt | C28: Noah | D28: 30 | E28: 20 | F28: 18 | G28: 15 | H28: 4 | I28: 0 | J28: =SUM(D28:H28)-IF(I28>1,5*(I28-1),0)
A29: aiqbal87 | B29: Iqbal | C29: Anika | D29: 28 | E29: 29 | F29: 14 | G29: 15 | H29: 3 | I29: 0 | J29: =SUM(D29:H29)-IF(I29>1,5*(I29-1),0) | K29: nice test coverage
A30: ciqbal17 | B30: Iqbal | C30: Caleb | D30: 29 | E30: 27 | F30: 20 | G30: 14 | H30: 3 | I30: 0 | J30: =SUM(D30:H30)-IF(I30>1,5*(I30-1),0)
A31: bjense80 | B31: Jensen | C31: Ben | D31: 27 | E31: 30 | F31: 20 | G31: 15 | H31: 4 | I31: 0 | J31: =SUM(D31:H31)-IF(I31>1,5*(I31-1),0)
A32: kjense36 | B32: Jensen | C32: Kyle | D32: 30 | E32: 20 | F32: 18 | G32: 14 | H32: 4 | I32: 0 | J32: =SUM(D32:H32)-IF(I32>1,5*(I32-1),0)
A33: ljense7 | B33: Jensen | C33: Leah | D33: 30 | E33: 30 | F33: 19 | G33: 14 | H33: 5 | I33: 0 | J33: =SUM(D33:H33)-IF(I33>1,5*(I33-1),0) | K33: no error handling on fetch
A34: kjorda48 | B34: Jordan | C34: Kyle | D34: 30 | E34: 30 | F34: 20 | G34: 14 | H34: 5 | I34: 0 | J34: =SUM(D34:H34)-IF(I34>1,5*(I34-1),0)
A35: mkaur50 | B35: Kaur | C35: Marco | D35: 27 | E35: 28 | F35: 17 | G35: 13 | H35: 3 | I35: 1 | J35: =SUM(D35:H35)-IF(I35>1,5*(I35-1),0)
A36: bkowal95 | B36: Kowalski | C36: Ben | D36: 30 | E36: 29 | F36: 20 | G36: 14 | H36: 3 | I36: 0 | J36: =SUM(D36:H36)-IF(I36>1,5*(I36-1),0)
A37: nkowal51 | B37: Kowalski | C37: Nadia | D37: 28 | E37: 20 | F37: 17 | G37: 15 | H37: 5 | I37: 1 | J37: =SUM(D37:H37)-IF(I37>1,5*(I37-1),0) | K37: hard-coded API key in config, -2
A38: okowal27 | B38: Kowalski | C38: Owen | D38: 30 | E38: 29 | F38: 17 | G38: 15 | H38: 4 | I38: 0 | J38: =SUM(D38:H38)-IF(I38>1,5*(I38-1),0) | K38: README missing run instructions
A39: skowal11 | B39: Kowalski | C39: Sara | D39: 20 | E39: 29 | F39: 20 | G39: 10 | H39: 5 | I39: 0 | J39: =SUM(D39:H39)-IF(I39>1,5*(I39-1),0) | K39: hard-coded API key in config, -2
A40: dlowe11 | B40: Lowe | C40: Daniel | D40: 28 | E40: 29 | F40: 20 | G40: 10 | H40: 5 | I40: 0 | J40: =SUM(D40:H40)-IF(I40>1,5*(I40-1),0)
...

Sheet P4
A1: PID | B1: Last | C1: First | D1: React views (25) | E1: State mgmt (20) | F1: API integration (20) | G1: Accessibility (10) | H1: Tests (15) | I1: Demo video (10) | J1: Late days | K1: Total | L1: Comment
A2: aalvar73 | B2: Alvarez | C2: Anika | D2: 17 | E2: 19 | F2: 19 | G2: 7 | H2: 15 | I2: 7 | J2: 0 | K2: =SUM(D2:I2)-IF(J2>1,5*(J2-1),0) | L2: nice test coverage
A3: halvar44 | B3: Alvarez | C3: Hana | D3: 17 | E3: 19 | F3: 20 | G3: 7 | H3: 15 | I3: 10 | J3: 0 | K3: =SUM(D3:I3)-IF(J3>1,5*(J3-1),0) | L3: nice test coverage
A4: ebarne26 | B4: Barnes | C4: Ellie | D4: 22 | E4: 19 | F4: 20 | G4: 7 | H4: 14 | I4: 10 | J4: 0 | K4: =SUM(D4:I4)-IF(J4>1,5*(J4-1),0)
A5: lbarne46 | B5: Barnes | C5: Lucas | D5: 22 | E5: 19 | F5: 14 | G5: 9 | H5: 14 | I5: 7 | J5: 0 | K5: =SUM(D5:I5)-IF(J5>1,5*(J5-1),0) | L5: hard-coded API key in config, -2
A6: vbarne79 | B6: Barnes | C6: Victor | D6: 24 | E6: 20 | F6: 14 | G6: 10 | H6: 15 | I6: 10 | J6: 0 | K6: =SUM(D6:I6)-IF(J6>1,5*(J6-1),0)
A7: jbenne73 | B7: Bennett | C7: Jacob | D7: 24 | E7: 20 | F7: 19 | G7: 10 | H7: 10 | I7: 10 | J7: 0 | K7: =SUM(D7:I7)-IF(J7>1,5*(J7-1),0) | L7: hard-coded API key in config, -2
A8: ecasti77 | B8: Castillo | C8: Ethan | D8: 25 | E8: 19 | F8: 20 | G8: 9 | H8: 14 | I8: 7 | J8: 0 | K8: =SUM(D8:I8)-IF(J8>1,5*(J8-1),0)
A9: gcasti55 | B9: Castillo | C9: Grace | D9: 24 | E9: 19 | F9: 20 | G9: 9 | H9: 14 | I9: 7 | J9: 0 | K9: =SUM(D9:I9)-IF(J9>1,5*(J9-1),0)
A10: lcasti27 | B10: Castillo | C10: Leah | D10: 24 | E10: 20 | F10: 19 | G10: 10 | H10: 13 | I10: 10 | J10: 0 | K10: =SUM(D10:I10)-IF(J10>1,5*(J10-1),0) | L10: no error handling on fetch
A11: rchowd60 | B11: Chowdhury | C11: Rosa | D11: 22 | E11: 20 | F11: 14 | G11: 10 | H11: 15 | I11: 8 | J11: 0 | K11: =SUM(D11:I11)-IF(J11>1,5*(J11-1),0) | L11: README missing run instructions
A12: cdawso9 | B12: Dawson | C12: Chloe | D12: 25 | E12: 19 | F12: 14 | G12: 8 | H12: 14 | I12: 7 | J12: 0 | K12: =SUM(D12:I12)-IF(J12>1,5*(J12-1),0) | L12: routes not RESTful
A13: gdawso56 | B13: Dawson | C13: Grace | D13: 25 | E13: 20 | F13: 20 | G13: 10 | H13: 13 | I13: 7 | J13: 0 | K13: =SUM(D13:I13)-IF(J13>1,5*(J13-1),0) | L13: no error handling on fetch
A14: ldawso94 | B14: Dawson | C14: Logan | D14: 25 | E14: 19 | F14: 17 | G14: 10 | H14: 15 | I14: 10 | J14: 0 | K14: =SUM(D14:I14)-IF(J14>1,5*(J14-1),0) | L14: no error handling on fetch
A15: rdawso79 | B15: Dawson | C15: Ryan | D15: 22 | E15: 18 | F15: 20 | G15: 9 | H15: 14 | I15: 10 | J15: 0 | K15: =SUM(D15:I15)-IF(J15>1,5*(J15-1),0)
A16: mdelga29 | B16: Delgado | C16: Maya | D16: 24 | E16: 17 | F16: 20 | G16: 8 | H16: 13 | I16: 7 | J16: 0 | K16: =SUM(D16:I16)-IF(J16>1,5*(J16-1),0) | L16: hard-coded API key in config, -2
A17: dellis12 | B17: Ellis | C17: Daniel | D17: 24 | E17: 18 | F17: 20 | G17: 9 | H17: 12 | I17: 10 | J17: 0 | K17: =SUM(D17:I17)-IF(J17>1,5*(J17-1),0) | L17: routes not RESTful
A18: cfitzg19 | B18: Fitzgerald | C18: Caleb | D18: 25 | E18: 14 | F18: 17 | G18: 7 | H18: 15 | I18: 8 | J18: 0 | K18: =SUM(D18:I18)-IF(J18>1,5*(J18-1),0) | L18: nice test coverage
A19: efitzg9 | B19: Fitzgerald | C19: Ethan | D19: 25 | E19: 18 | F19: 20 | G19: 10 | H19: 12 | I19: 7 | J19: 0 | K19: =SUM(D19:I19)-IF(J19>1,5*(J19-1),0) | L19: hard-coded API key in config, -2
A20: vfitzg44 | B20: Fitzgerald | C20: Victor | D20: 17 | E20: 19 | F20: 20 | G20: 8 | H20: 15 | I20: 10 | J20: 2 | K20: =SUM(D20:I20)-IF(J20>1,5*(J20-1),0) | L20: nice test coverage
A21: nfoste50 | B21: Foster | C21: Noah | D21: 25 | E21: 19 | F21: 19 | G21: 10 | H21: 15 | I21: 10 | J21: 0 | K21: =SUM(D21:I21)-IF(J21>1,5*(J21-1),0)
A22: agreen67 | B22: Greene | C22: Arjun | D22: 24 | E22: 18 | F22: 17 | G22: 10 | H22: 13 | I22: 9 | J22: 0 | K22: =SUM(D22:I22)-IF(J22>1,5*(J22-1),0)
A23: igreen46 | B23: Greene | C23: Isabel | D23: 25 | E23: 20 | F23: 14 | G23: 8 | H23: 13 | I23: 8 | J23: 0 | K23: =SUM(D23:I23)-IF(J23>1,5*(J23-1),0) | L23: great UI polish
A24: mgreen47 | B24: Greene | C24: Marco | D24: 24 | E24: 20 | F24: 14 | G24: 9 | H24: 14 | I24: 8 | J24: 0 | K24: =SUM(D24:I24)-IF(J24>1,5*(J24-1),0)
A25: agupta99 | B25: Gupta | C25: Anika | D25: 22 | E25: 14 | F25: 20 | G25: 9 | H25: 15 | I25: 7 | J25: 0 | K25: =SUM(D25:I25)-IF(J25>1,5*(J25-1),0)
A26: khale16 | B26: Hale | C26: Kyle | D26: 25 | E26: 14 | F26: 20 | G26: 9 | H26: 14 | I26: 9 | J26: 0 | K26: =SUM(D26:I26)-IF(J26>1,5*(J26-1),0) | L26: routes not RESTful
A27: shale29 | B27: Hale | C27: Sofia | D27: 25 | E27: 17 | F27: 17 | G27: 10 | H27: 15 | I27: 9 | J27: 0 | K27: =SUM(D27:I27)-IF(J27>1,5*(J27-1),0) | L27: hard-coded API key in config, -2
A28: nholt27 | B28: Holt | C28: Noah | D28: 17 | E28: 17 | F28: 14 | G28: 7 | H28: 15 | I28: 9 | J28: 0 | K28: =SUM(D28:I28)-IF(J28>1,5*(J28-1),0) | L28: no error handling on fetch
A29: aiqbal87 | B29: Iqbal | C29: Anika | D29: 25 | E29: 19 | F29: 14 | G29: 10 | H29: 15 | I29: 9 | J29: 0 | K29: =SUM(D29:I29)-IF(J29>1,5*(J29-1),0)
A30: ciqbal17 | B30: Iqbal | C30: Caleb | D30: 23 | E30: 20 | F30: 17 | G30: 10 | H30: 13 | I30: 10 | J30: 0 | K30: =SUM(D30:I30)-IF(J30>1,5*(J30-1),0) | L30: no error handling on fetch
A31: bjense80 | B31: Jensen | C31: Ben | D31: 24 | E31: 20 | F31: 19 | G31: 10 | H31: 10 | I31: 8 | J31: 0 | K31: =SUM(D31:I31)-IF(J31>1,5*(J31-1),0) | L31: hard-coded API key in config, -2
A32: kjense36 | B32: Jensen | C32: Kyle | D32: 24 | E32: 20 | F32: 18 | G32: 7 | H32: 14 | I32: 10 | J32: 0 | K32: =SUM(D32:I32)-IF(J32>1,5*(J32-1),0) | L32: no error handling on fetch
A33: ljense7 | B33: Jensen | C33: Leah | D33: 25 | E33: 20 | F33: 17 | G33: 9 | H33: 14 | I33: 9 | J33: 0 | K33: =SUM(D33:I33)-IF(J33>1,5*(J33-1),0) | L33: nice test coverage
A34: kjorda48 | B34: Jordan | C34: Kyle | D34: 22 | E34: 20 | F34: 20 | G34: 10 | H34: 10 | I34: 10 | J34: 0 | K34: =SUM(D34:I34)-IF(J34>1,5*(J34-1),0) | L34: nice test coverage
A35: mkaur50 | B35: Kaur | C35: Marco | D35: 22 | E35: 14 | F35: 20 | G35: 10 | H35: 15 | I35: 9 | J35: 0 | K35: =SUM(D35:I35)-IF(J35>1,5*(J35-1),0)
A36: bkowal95 | B36: Kowalski | C36: Ben | D36: 22 | E36: 20 | F36: 20 | G36: 9 | H36: 15 | I36: 10 | J36: 2 | K36: =SUM(D36:I36)-IF(J36>1,5*(J36-1),0) | L36: nice test coverage
A37: nkowal51 | B37: Kowalski | C37: Nadia | D37: 24 | E37: 20 | F37: 20 | G37: 8 | H37: 14 | I37: 10 | J37: 0 | K37: =SUM(D37:I37)-IF(J37>1,5*(J37-1),0)
A38: okowal27 | B38: Kowalski | C38: Owen | D38: 24 | E38: 14 | F38: 19 | G38: 10 | H38: 15 | I38: 9 | J38: 2 | K38: =SUM(D38:I38)-IF(J38>1,5*(J38-1),0) | L38: nice test coverage
A39: skowal11 | B39: Kowalski | C39: Sara | D39: 17 | E39: 14 | F39: 20 | G39: 8 | H39: 15 | I39: 7 | J39: 0 | K39: =SUM(D39:I39)-IF(J39>1,5*(J39-1),0) | L39: great UI polish
A40: dlowe11 | B40: Lowe | C40: Daniel | D40: 24 | E40: 19 | F40: 20 | G40: 10 | H40: 12 | I40: 10 | J40: 0 | K40: =SUM(D40:I40)-IF(J40>1,5*(J40-1),0)
...

Sheet Final
A1: Team | B1: Members (PIDs) | C1: Proposal (10) | D1: Milestone (20) | E1: Final demo (40) | F1: Report (20) | G1: Peer eval (10) | H1: Total
A2: Team 01 | B2: aalvar73, halvar44, ebarne26, lbarne46 | C2: 9 | D2: 19 | E2: 37 | F2: 19 | G2: 9 | H2: =SUM(C2:G2)
A3: Team 02 | B3: vbarne79, jbenne73, ecasti77, gcasti55 | C3: 10 | D3: 16 | E3: 38 | F3: 19 | G3: 9 | H3: =SUM(C3:G3)
A4: Team 03 | B4: lcasti27, rchowd60, cdawso9, gdawso56 | C4: 10 | D4: 20 | E4: 32 | F4: 18 | G4: 10 | H4: =SUM(C4:G4)
A5: Team 04 | B5: ldawso94, rdawso79, mdelga29, dellis12 | C5: 10 | D5: 18 | E5: 40 | F5: 17 | G5: 10 | H5: =SUM(C5:G5)
A6: Team 05 | B6: cfitzg19, efitzg9, vfitzg44, nfoste50 | C6: 9 | D6: 20 | E6: 35 | F6: 18 | G6: 10 | H6: =SUM(C6:G6)
A7: Team 06 | B7: agreen67, igreen46, mgreen47, agupta99 | C7: 8 | D7: 20 | E7: 37 | F7: 17 | G7: 9 | H7: =SUM(C7:G7)
A8: Team 07 | B8: khale16, shale29, nholt27, aiqbal87 | C8: 8 | D8: 20 | E8: 38 | F8: 19 | G8: 9 | H8: =SUM(C8:G8)
A9: Team 08 | B9: ciqbal17, bjense80, kjense36, ljense7 | C9: 10 | D9: 20 | E9: 35 | F9: 19 | G9: 10 | H9: =SUM(C9:G9)
A10: Team 09 | B10: kjorda48, mkaur50, bkowal95, nkowal51 | C10: 9 | D10: 19 | E10: 37 | F10: 20 | G10: 10 | H10: =SUM(C10:G10)
A11: Team 10 | B11: okowal27, skowal11, dlowe11, elowe23 | C11: 8 | D11: 18 | E11: 32 | F11: 19 | G11: 9 | H11: =SUM(C11:G11)
A12: Team 11 | B12: jlowe60, emendo45, mmendo55, jnakam87 | C12: 9 | D12: 20 | E12: 35 | F12: 17 | G12: 10 | H12: =SUM(C12:G12)
A13: Team 12 | B13: gokafo31, tokafo53, aprice22, lprice55 | C13: 10 | D13: 16 | E13: 35 | F13: 19 | G13: 10 | H13: =SUM(C13:G13)
... A17: Team 16 | B17: nwalsh38, zwalsh76, tyilma60, nzimme44 | C17: 8 | D17: 20 | E17: 38 | F17: 20 | G17: 10 | H17: =SUM(C17:G17)

Sheet Regrades
A1: Date | B1: PID | C1: Assignment | D1: Request | E1: Decision | F1: Points change | G1: Handled by
A2: 2025-11-03 | B2: gdawso56 | C2: P3 | D2: Tests criterion: autograder missed tests in /spec folder | E2: accepted, re-ran | F2: +6 | G2: David
A3: 2025-11-25 | B3: skowal11 | C3: P4 | D3: Late-day policy: claims 2nd late day should not count because Canvas was down 11/21 evening | E3: partially accepted: Canvas outage was 7-9 pm, submission at 11:48 pm next day; 1 late day waived | F3: +5 | G3: David + instructor
A4: 2025-11-26 | B4: skowal11 | C4: P4 | D4: follow-up: wants both late days waived | E4: denied per syllabus; instructor agreed | F4: 0 | G4: instructor
A5: 2025-12-12 | B5: esulli81 | C5: Final | D5: Peer eval: teammate gave 2/10 after a conflict | E5: replaced with team median | F5: +5 | G5: David
A6: 2025-12-14 | B6: jbenne73 | C6: P3 | D6: README criterion | E6: denied, README had no run instructions | F6: 0 | G6: David

Sheet Summary
A1: PID | B1: Last | C1: First | D1: P3 | E1: P4 | F1: Final (team) | G1: Regrade adj. | H1: Weighted (P3 25%, P4 25%, Final 50%)
A2: aalvar73 | B2: Alvarez | C2: Anika | D2: =P3!J2 | E2: =P4!K2 | F2: =Final!H2 | G2: =SUMIF(Regrades!B:B,A2,Regrades!F:F) | H2: =0.25*D2+0.25*E2+0.5*F2+G2
A3: halvar44 | B3: Alvarez | C3: Hana | D3: =P3!J3 | E3: =P4!K3 | F3: =Final!H2 | G3: =SUMIF(Regrades!B:B,A3,Regrades!F:F) | H3: =0.25*D3+0.25*E3+0.5*F3+G3
A4: ebarne26 | B4: Barnes | C4: Ellie | D4: =P3!J4 | E4: =P4!K4 | F4: =Final!H2 | G4: =SUMIF(Regrades!B:B,A4,Regrades!F:F) | H4: =0.25*D4+0.25*E4+0.5*F4+G4
A5: lbarne46 | B5: Barnes | C5: Lucas | D5: =P3!J5 | E5: =P4!K5 | F5: =Final!H2 | G5: =SUMIF(Regrades!B:B,A5,Regrades!F:F) | H5: =0.25*D5+0.25*E5+0.5*F5+G5
A6: vbarne79 | B6: Barnes | C6: Victor | D6: =P3!J6 | E6: =P4!K6 | F6: =Final!H3 | G6: =SUMIF(Regrades!B:B,A6,Regrades!F:F) | H6: =0.25*D6+0.25*E6+0.5*F6+G6
A7: jbenne73 | B7: Bennett | C7: Jacob | D7: =P3!J7 | E7: =P4!K7 | F7: =Final!H3 | G7: =SUMIF(Regrades!B:B,A7,Regrades!F:F) | H7: =0.25*D7+0.25*E7+0.5*F7+G7
A8: ecasti77 | B8: Castillo | C8: Ethan | D8: =P3!J8 | E8: =P4!K8 | F8: =Final!H3 | G8: =SUMIF(Regrades!B:B,A8,Regrades!F:F) | H8: =0.25*D8+0.25*E8+0.5*F8+G8
A9: gcasti55 | B9: Castillo | C9: Grace | D9: =P3!J9 | E9: =P4!K9 | F9: =Final!H3 | G9: =SUMIF(Regrades!B:B,A9,Regrades!F:F) | H9: =0.25*D9+0.25*E9+0.5*F9+G9
A10: lcasti27 | B10: Castillo | C10: Leah | D10: =P3!J10 | E10: =P4!K10 | F10: =Final!H4 | G10: =SUMIF(Regrades!B:B,A10,Regrades!F:F) | H10: =0.25*D10+0.25*E10+0.5*F10+G10
A11: rchowd60 | B11: Chowdhury | C11: Rosa | D11: =P3!J11 | E11: =P4!K11 | F11: =Final!H4 | G11: =SUMIF(Regrades!B:B,A11,Regrades!F:F) | H11: =0.25*D11+0.25*E11+0.5*F11+G11
A12: cdawso9 | B12: Dawson | C12: Chloe | D12: =P3!J12 | E12: =P4!K12 | F12: =Final!H4 | G12: =SUMIF(Regrades!B:B,A12,Regrades!F:F) | H12: =0.25*D12+0.25*E12+0.5*F12+G12
A13: gdawso56 | B13: Dawson | C13: Grace | D13: =P3!J13 | E13: =P4!K13 | F13: =Final!H4 | G13: =SUMIF(Regrades!B:B,A13,Regrades!F:F) | H13: =0.25*D13+0.25*E13+0.5*F13+G13
A14: ldawso94 | B14: Dawson | C14: Logan | D14: =P3!J14 | E14: =P4!K14 | F14: =Final!H5 | G14: =SUMIF(Regrades!B:B,A14,Regrades!F:F) | H14: =0.25*D14+0.25*E14+0.5*F14+G14
A15: rdawso79 | B15: Dawson | C15: Ryan | D15: =P3!J15 | E15: =P4!K15 | F15: =Final!H5 | G15: =SUMIF(Regrades!B:B,A15,Regrades!F:F) | H15: =0.25*D15+0.25*E15+0.5*F15+G15
A16: mdelga29 | B16: Delgado | C16: Maya | D16: =P3!J16 | E16: =P4!K16 | F16: =Final!H5 | G16: =SUMIF(Regrades!B:B,A16,Regrades!F:F) | H16: =0.25*D16+0.25*E16+0.5*F16+G16
A17: dellis12 | B17: Ellis | C17: Daniel | D17: =P3!J17 | E17: =P4!K17 | F17: =Final!H5 | G17: =SUMIF(Regrades!B:B,A17,Regrades!F:F) | H17: =0.25*D17+0.25*E17+0.5*F17+G17
A18: cfitzg19 | B18: Fitzgerald | C18: Caleb | D18: =P3!J18 | E18: =P4!K18 | F18: =Final!H6 | G18: =SUMIF(Regrades!B:B,A18,Regrades!F:F) | H18: =0.25*D18+0.25*E18+0.5*F18+G18
A19: efitzg9 | B19: Fitzgerald | C19: Ethan | D19: =P3!J19 | E19: =P4!K19 | F19: =Final!H6 | G19: =SUMIF(Regrades!B:B,A19,Regrades!F:F) | H19: =0.25*D19+0.25*E19+0.5*F19+G19
A20: vfitzg44 | B20: Fitzgerald | C20: Victor | D20: =P3!J20 | E20: =P4!K20 | F20: =Final!H6 | G20: =SUMIF(Regrades!B:B,A20,Regrades!F:F) | H20: =0.25*D20+0.25*E20+0.5*F20+G20
A21: nfoste50 | B21: Foster | C21: Noah | D21: =P3!J21 | E21: =P4!K21 | F21: =Final!H6 | G21: =SUMIF(Regrades!B:B,A21,Regrades!F:F) | H21: =0.25*D21+0.25*E21+0.5*F21+G21
A22: agreen67 | B22: Greene | C22: Arjun | D22: =P3!J22 | E22: =P4!K22 | F22: =Final!H7 | G22: =SUMIF(Regrades!B:B,A22,Regrades!F:F) | H22: =0.25*D22+0.25*E22+0.5*F22+G22
A23: igreen46 | B23: Greene | C23: Isabel | D23: =P3!J23 | E23: =P4!K23 | F23: =Final!H7 | G23: =SUMIF(Regrades!B:B,A23,Regrades!F:F) | H23: =0.25*D23+0.25*E23+0.5*F23+G23
A24: mgreen47 | B24: Greene | C24: Marco | D24: =P3!J24 | E24: =P4!K24 | F24: =Final!H7 | G24: =SUMIF(Regrades!B:B,A24,Regrades!F:F) | H24: =0.25*D24+0.25*E24+0.5*F24+G24
A25: agupta99 | B25: Gupta | C25: Anika | D25: =P3!J25 | E25: =P4!K25 | F25: =Final!H7 | G25: =SUMIF(Regrades!B:B,A25,Regrades!F:F) | H25: =0.25*D25+0.25*E25+0.5*F25+G25
A26: khale16 | B26: Hale | C26: Kyle | D26: =P3!J26 | E26: =P4!K26 | F26: =Final!H8 | G26: =SUMIF(Regrades!B:B,A26,Regrades!F:F) | H26: =0.25*D26+0.25*E26+0.5*F26+G26
A27: shale29 | B27: Hale | C27: Sofia | D27: =P3!J27 | E27: =P4!K27 | F27: =Final!H8 | G27: =SUMIF(Regrades!B:B,A27,Regrades!F:F) | H27: =0.25*D27+0.25*E27+0.5*F27+G27
A28: nholt27 | B28: Holt | C28: Noah | D28: =P3!J28 | E28: =P4!K28 | F28: =Final!H8 | G28: =SUMIF(Regrades!B:B,A28,Regrades!F:F) | H28: =0.25*D28+0.25*E28+0.5*F28+G28
A29: aiqbal87 | B29: Iqbal | C29: Anika | D29: =P3!J29 | E29: =P4!K29 | F29: =Final!H8 | G29: =SUMIF(Regrades!B:B,A29,Regrades!F:F) | H29: =0.25*D29+0.25*E29+0.5*F29+G29
A30: ciqbal17 | B30: Iqbal | C30: Caleb | D30: =P3!J30 | E30: =P4!K30 | F30: =Final!H9 | G30: =SUMIF(Regrades!B:B,A30,Regrades!F:F) | H30: =0.25*D30+0.25*E30+0.5*F30+G30
A31: bjense80 | B31: Jensen | C31: Ben | D31: =P3!J31 | E31: =P4!K31 | F31: =Final!H9 | G31: =SUMIF(Regrades!B:B,A31,Regrades!F:F) | H31: =0.25*D31+0.25*E31+0.5*F31+G31
A32: kjense36 | B32: Jensen | C32: Kyle | D32: =P3!J32 | E32: =P4!K32 | F32: =Final!H9 | G32: =SUMIF(Regrades!B:B,A32,Regrades!F:F) | H32: =0.25*D32+0.25*E32+0.5*F32+G32
A33: ljense7 | B33: Jensen | C33: Leah | D33: =P3!J33 | E33: =P4!K33 | F33: =Final!H9 | G33: =SUMIF(Regrades!B:B,A33,Regrades!F:F) | H33: =0.25*D33+0.25*E33+0.5*F33+G33
A34: kjorda48 | B34: Jordan | C34: Kyle | D34: =P3!J34 | E34: =P4!K34 | F34: =Final!H10 | G34: =SUMIF(Regrades!B:B,A34,Regrades!F:F) | H34: =0.25*D34+0.25*E34+0.5*F34+G34
A35: mkaur50 | B35: Kaur | C35: Marco | D35: =P3!J35 | E35: =P4!K35 | F35: =Final!H10 | G35: =SUMIF(Regrades!B:B,A35,Regrades!F:F) | H35: =0.25*D35+0.25*E35+0.5*F35+G35
A36: bkowal95 | B36: Kowalski | C36: Ben | D36: =P3!J36 | E36: =P4!K36 | F36: =Final!H10 | G36: =SUMIF(Regrades!B:B,A36,Regrades!F:F) | H36: =0.25*D36+0.25*E36+0.5*F36+G36
A37: nkowal51 | B37: Kowalski | C37: Nadia | D37: =P3!J37 | E37: =P4!K37 | F37: =Final!H10 | G37: =SUMIF(Regrades!B:B,A37,Regrades!F:F) | H37: =0.25*D37+0.25*E37+0.5*F37+G37
A38: okowal27 | B38: Kowalski | C38: Owen | D38: =P3!J38 | E38: =P4!K38 | F38: =Final!H11 | G38: =SUMIF(Regrades!B:B,A38,Regrades!F:F) | H38: =0.25*D38+0.25*E38+0.5*F38+G38
A39: skowal11 | B39: Kowalski | C39: Sara | D39: =P3!J39 | E39: =P4!K39 | F39: =Final!H11 | G39: =SUMIF(Regrades!B:B,A39,Regrades!F:F) | H39: =0.25*D39+0.25*E39+0.5*F39+G39
A40: dlowe11 | B40: Lowe | C40: Daniel | D40: =P3!J40 | E40: =P4!K40 | F40: =Final!H11 | G40: =SUMIF(Regrades!B:B,A40,Regrades!F:F) | H40: =0.25*D40+0.25*E40+0.5*F40+G40
...
